Workbook

Sheet Consolidate rows
A1: Consolidate rows in Excel with formulas
A2: Date | B2: Department | C2: Amount | E2: Department | F2: Amount
A3: 45658 | B3: Sales | C3: 1250 | E3: Sales | F3: 10960
A4: 45658 | B4: Marketing | C4: 980 | E4: Marketing | F4: 5280
A5: 45660 | B5: Sales | C5: 1540 | E5: Support | F5: 2690
A6: 45661 | B6: Support | C6: 620 | E6: Finance | F6: 8410
A7: 45662 | B7: Sales | C7: 1310
A8: 45663 | B8: Finance | C8: 2200
A9: 45664 | B9: Marketing | C9: 1120
A10: 45665 | B10: Support | C10: 700
A11: 45667 | B11: Sales | C11: 1890
A12: 45667 | B12: Finance | C12: 1760
A13: 45669 | B13: Marketing | C13: 1050
A14: 45669 | B14: Sales | C14: 1420
A15: 45670 | B15: Support | C15: 660
A16: 45671 | B16: Finance | C16: 2340
A17: 45672 | B17: Sales | C17: 1670
A18: 45673 | B18: Marketing | C18: 930
... A22: 45677 | B22: Marketing | C22: 1200

Sheet Consolidate columns
A1: Consolidate columns in Excel with formulas
A2: Department | B2: Jan | C2: Feb | D2: Mar | E2: Total | F2: Average
A3: Administration | B3: 1200 | C3: 1400 | D3: 1650 | E3: =SUM(B3:D3) -> 4250 | F3: =AVERAGE(B3:D3) -> 1416.6667
A4: Customer Support | B4: 1450 | C4: 1320 | D4: 1750 | E4: =SUM(B4:D4) -> 4520 | F4: =AVERAGE(B4:D4) -> 1506.6667
A5: Finance | B5: 1600 | C5: 1600 | D5: 1180 | E5: =SUM(B5:D5) -> 4380 | F5: =AVERAGE(B5:D5) -> 1460
A6: Human Resources | B6: 1150 | C6: 1750 | D6: 1450 | E6: =SUM(B6:D6) -> 4350 | F6: =AVERAGE(B6:D6) -> 1450
A7: Information Technology | B7: 1250 | C7: 1800 | D7: 2000 | E7: =SUM(B7:D7) -> 5050 | F7: =AVERAGE(B7:D7) -> 1683.3333
A8: Legal | B8: 1850 | C8: 1500 | D8: 1120 | E8: =SUM(B8:D8) -> 4470 | F8: =AVERAGE(B8:D8) -> 1490
A9: Logistics | B9: 1350 | C9: 1010 | D9: 1250 | E9: =SUM(B9:D9) -> 3610 | F9: =AVERAGE(B9:D9) -> 1203.3333
A10: Marketing | B10: 1200 | C10: 1550 | D10: 1550 | E10: =SUM(B10:D10) -> 4300 | F10: =AVERAGE(B10:D10) -> 1433.3333
A11: Operations | B11: 1950 | C11: 1700 | D11: 1900 | E11: =SUM(B11:D11) -> 5550 | F11: =AVERAGE(B11:D11) -> 1850
A12: Procurement | B12: 1350 | C12: 1080 | D12: 1500 | E12: =SUM(B12:D12) -> 3930 | F12: =AVERAGE(B12:D12) -> 1310
A13: Product Management | B13: 1400 | C13: 1000 | D13: 1650 | E13: =SUM(B13:D13) -> 4050 | F13: =AVERAGE(B13:D13) -> 1350
A14: Quality Assurance | B14: 1100 | C14: 1450 | D14: 1600 | E14: =SUM(B14:D14) -> 4150 | F14: =AVERAGE(B14:D14) -> 1383.3333
... A17: Training and Development | B17: 1500 | C17: 1050 | D17: 1400 | E17: =SUM(B17:D17) -> 3950 | F17: =AVERAGE(B17:D17) -> 1316.6667

Sheet consolidation
A1: Item | B1: Jan | C1: Feb | D1: Mar
B2: ='Report 1'!$H$2 -> 400 | C2: ='Report 1'!$I$2 -> 310 | D2: ='Report 1'!$J$2 -> 170
B3: ='Report 2'!$G$4 -> 160 | C3: ='Report 2'!$H$4 -> 170 | D3: ='Report 2'!$I$4 -> 200
B4: ='Report 3'!$B$2 -> 170 | C4: ='Report 3'!$C$2 -> 400 | D4: ='Report 3'!$D$2 -> 235
B5: =SUM(B2:B4) -> 730 | C5: =SUM(C2:C4) -> 880 | D5: =SUM(D2:D4) -> 605
B6: ='Report 1'!$H$3 -> 170 | C6: ='Report 1'!$I$3 -> 250 | D6: ='Report 1'!$J$3 -> 220
B7: ='Report 2'!$G$5 -> 220 | C7: ='Report 2'!$H$5 -> 270 | D7: ='Report 2'!$I$5 -> 190
B8: ='Report 3'!$B$3 -> 155 | C8: ='Report 3'!$C$3 -> 160 | D8: ='Report 3'!$D$3 -> 260
B9: =SUM(B6:B8) -> 545 | C9: =SUM(C6:C8) -> 680 | D9: =SUM(D6:D8) -> 670
B10: ='Report 1'!$H$4 -> 110 | D10: ='Report 1'!$J$4 -> 340
B11: ='Report 2'!$G$6 -> 245 | C11: ='Report 2'!$H$6 -> 240 | D11: ='Report 2'!$I$6 -> 235
B12: ='Report 3'!$B$4 -> 320 | C12: ='Report 3'!$C$4 -> 175 | D12: ='Report 3'!$D$4 -> 235
B13: =SUM(B10:B12) -> 675 | C13: =SUM(C10:C12) -> 415 | D13: =SUM(D10:D12) -> 810
B14: ='Report 1'!$H$5 -> 120 | C14: ='Report 1'!$I$5 -> 180 | D14: ='Report 1'!$J$5 -> 160
B15: ='Report 2'!$G$7 -> 140 | C15: ='Report 2'!$H$7 -> 145 | D15: ='Report 2'!$I$7 -> 140
B16: ='Report 3'!$B$5 -> 270 | C16: ='Report 3'!$C$5 -> 460 | D16: ='Report 3'!$D$5 -> 190
B17: =SUM(B14:B16) -> 530 | C17: =SUM(C14:C16) -> 785 | D17: =SUM(D14:D16) -> 490
B18: ='Report 1'!$H$6 -> 210 | C18: ='Report 1'!$I$6 -> 300 | D18: ='Report 1'!$J$6 -> 270
B19: ='Report 2'!$G$8 -> 130 | C19: ='Report 2'!$H$8 -> 250 | D19: ='Report 2'!$I$8 -> 190
B20: ='Report 3'!$B$6 -> 190 | C20: ='Report 3'!$C$6 -> 160 | D20: ='Report 3'!$D$6 -> 250
B21: =SUM(B18:B20) -> 530 | C21: =SUM(C18:C20) -> 710 | D21: =SUM(D18:D20) -> 710
B22: ='Report 1'!$H$7 -> 180 | C22: ='Report 1'!$I$7 -> 260 | D22: ='Report 1'!$J$7 -> 210
B23: ='Report 2'!$G$9 -> 210 | C23: ='Report 2'!$H$9 -> 110 | D23: ='Report 2'!$I$9 -> 150
B24: ='Report 3'!$B$7 -> 145 | C24: ='Report 3'!$C$7 -> 220 | D24: ='Report 3'!$D$7 -> 300
B25: =SUM(B22:B24) -> 535 | C25: =SUM(C22:C24) -> 590 | D25: =SUM(D22:D24) -> 660
B26: ='Report 1'!$H$8 -> 130 | C26: ='Report 1'!$I$8 -> 190 | D26: ='Report 1'!$J$8 -> 150
B27: ='Report 2'!$G$10 -> 310 | C27: ='Report 2'!$H$10 -> 150 | D27: ='Report 2'!$I$10 -> 190
B28: ='Report 3'!$B$8 -> 310 | C28: ='Report 3'!$C$8 -> 140 | D28: ='Report 3'!$D$8 -> 160
B29: =SUM(B26:B28) -> 750 | C29: =SUM(C26:C28) -> 480 | D29: =SUM(D26:D28) -> 500
B30: ='Report 1'!$H$9 -> 175 | C30: ='Report 1'!$I$9 -> 245 | D30: ='Report 1'!$J$9 -> 215
B31: ='Report 2'!$G$11 -> 180 | C31: ='Report 2'!$H$11 -> 290 | D31: ='Report 2'!$I$11 -> 205
B32: ='Report 3'!$B$9 -> 150 | C32: ='Report 3'!$C$9 -> 250 | D32: ='Report 3'!$D$9 -> 210
B33: =SUM(B30:B32) -> 505 | C33: =SUM(C30:C32) -> 785 | D33: =SUM(D30:D32) -> 630
B34: ='Report 1'!$H$10 -> 150 | C34: ='Report 1'!$I$10 -> 210 | D34: ='Report 1'!$J$10 -> 190
B35: ='Report 2'!$G$12 -> 100 | C35: ='Report 2'!$H$12 -> 210 | D35: ='Report 2'!$I$12 -> 220
B36: ='Report 3'!$B$10 -> 140 | C36: ='Report 3'!$C$10 -> 270 | D36: ='Report 3'!$D$10 -> 205
B37: =SUM(B34:B36) -> 390 | C37: =SUM(C34:C36) -> 690 | D37: =SUM(D34:D36) -> 615
B38: ='Report 1'!$H$11 -> 160 | D38: ='Report 1'!$J$11 -> 180
B39: ='Report 2'!$G$13 -> 215 | C39: ='Report 2'!$H$13 -> 200 | D39: ='Report 2'!$I$13 -> 185
B40: ='Report 3'!$B$11 -> 290 | C40: ='Report 3'!$C$11 -> 245 | D40: ='Report 3'!$D$11 -> 180
...

Sheet Report 1
G1: Item | H1: Jan | I1: Feb | J1: Mar
G2: Biscuits | H2: 400 | I2: 310 | J2: 170
G3: Brownies | H3: 170 | I3: 250 | J3: 220
G4: Cakes | H4: 110 | J4: 340
G5: Candy Bars | H5: 120 | I5: 180 | J5: 160
G6: Cheesecake | H6: 210 | I6: 300 | J6: 270
G7: Chocolate | H7: 180 | I7: 260 | J7: 210
G8: Cookies | H8: 130 | I8: 190 | J8: 150
G9: Croissants | H9: 175 | I9: 245 | J9: 215
G10: Cupcakes | H10: 150 | I10: 210 | J10: 190
G11: Donuts | H11: 160 | J11: 180
G12: Fudge | H12: 165 | I12: 235 | J12: 205
G13: Ice-cream | H13: 110 | I13: 220 | J13: 160
G14: Macarons | H14: 220 | I14: 310 | J14: 280
G15: Muffins | H15: 140 | I15: 200 | J15: 170
G16: Pancakes | H16: 155 | I16: 215 | J16: 185
G17: Pastries | H17: 190 | I17: 270 | J17: 240
G18: Pies | H18: 200 | I18: 290
G19: Sweets | H19: 250 | I19: 140 | J19: 200
G20: Tarts | H20: 185 | I20: 265 | J20: 235
G21: Waffles | H21: 145 | I21: 205 | J21: 175

Sheet Report 2
F3: Item | G3: Jan | H3: Feb | I3: Mar
F4: Waffles | G4: 160 | H4: 170 | I4: 200
F5: Tarts | G5: 220 | H5: 270 | I5: 190
F6: Sweets | G6: 245 | H6: 240 | I6: 235
F7: Pies | G7: 140 | H7: 145 | I7: 140
F8: Pastries | G8: 130 | H8: 250 | I8: 190
F9: Pancakes | G9: 210 | H9: 110 | I9: 150
F10: Muffins | G10: 310 | H10: 150 | I10: 190
F11: Macarons | G11: 180 | H11: 290 | I11: 205
F12: Ice-cream | G12: 100 | H12: 210 | I12: 220
F13: Fudge | G13: 215 | H13: 200 | I13: 185
F14: Donuts | G14: 140 | H14: 215 | I14: 200
F15: Cupcakes | G15: 180 | H15: 210 | I15: 120
... F19: Cheesecake | G19: 180 | H19: 250 | I19: 165
F20: Candy Bars | G20: 280 | H20: 175
F21: Cakes | G21: 310 | I21: 220
F22: Brownies | G22: 235 | H22: 205 | I22: 175
F23: Biscuits | G23: 170 | H23: 185 | I23: 300

Sheet Report 3
A1: Item | B1: Jan | C1: Feb | D1: Mar
A2: Sweets | B2: 170 | C2: 400 | D2: 235 | K2: Jan | L2: Feb | M2: Mar
A3: Biscuits | B3: 155 | C3: 160 | D3: 260 | J3: Biscuits | K3: 725 | L3: 655 | M3: 730
A4: Ice-cream | B4: 320 | C4: 175 | D4: 235 | J4: Brownies | K4: 545 | L4: 725 | M4: 600
A5: Cakes | B5: 270 | C5: 460 | D5: 190 | J5: Cakes | K5: 690 | L5: 460 | M5: 750
A6: Chocolate | B6: 190 | C6: 160 | D6: 250 | J6: Candy Bars | K6: 590 | L6: 555 | M6: 280
A7: Cookies | B7: 145 | C7: 220 | D7: 300 | J7: Cheesecake | K7: 730 | L7: 720 | M7: 585
A8: Donuts | B8: 310 | C8: 140 | D8: 160 | J8: Chocolate | K8: 710 | L8: 575 | M8: 630
A9: Muffins | B9: 150 | C9: 250 | D9: 210 | J9: Cookies | K9: 540 | L9: 680 | M9: 710
A10: Brownies | B10: 140 | C10: 270 | D10: 205 | J10: Croissants | K10: 545 | L10: 665 | M10: 590
A11: Cupcakes | B11: 290 | C11: 245 | D11: 180 | J11: Cupcakes | K11: 620 | L11: 665 | M11: 490
A12: Pastries | C12: 100 | D12: 220 | J12: Donuts | K12: 610 | L12: 355 | M12: 540
A13: Candy Bars | B13: 190 | C13: 200 | D13: 120 | J13: Fudge | K13: 580 | L13: 675 | M13: 560
A14: Pies | B14: 165 | D14: 130 | J14: Ice-cream | K14: 530 | L14: 605 | M14: 615
A15: Waffles | B15: 200 | C15: 210 | D15: 175 | J15: Macarons | K15: 615 | L15: 785 | M15: 625
A16: Pancakes | B16: 180 | C16: 280 | D16: 265 | J16: Muffins | K16: 600 | L16: 600 | M16: 570
A17: Croissants | B17: 210 | C17: 310 | D17: 215 | J17: Pancakes | K17: 545 | L17: 605 | M17: 600
A18: Macarons | B18: 215 | C18: 185 | D18: 140 | J18: Pastries | K18: 320 | L18: 620 | M18: 650
A19: Fudge | B19: 200 | C19: 240 | D19: 170 | J19: Pies | K19: 505 | L19: 435 | M19: 270
A20: Cheesecake | B20: 340 | C20: 170 | D20: 150 | J20: Sweets | K20: 665 | L20: 780 | M20: 670
A21: Tarts | B21: 110 | C21: 220 | D21: 180 | J21: Tarts | K21: 515 | L21: 755 | M21: 605
J22: Waffles | K22: 505 | L22: 585 | M22: 550

Sheet dynamic
D2: Jan | E2: Feb | F2: Mar
C3: Excel-Consolidate-Data | D3: ='Report 1'!$H$2 -> 400 | E3: ='Report 1'!$I$2 -> 310 | F3: ='Report 1'!$J$2 -> 170
C4: Excel-Consolidate-Data | D4: ='Report 2'!$G$23 -> 170 | E4: ='Report 2'!$H$23 -> 185 | F4: ='Report 2'!$I$23 -> 300
C5: Excel-Consolidate-Data | D5: ='Report 3'!$B$3 -> 155 | E5: ='Report 3'!$C$3 -> 160 | F5: ='Report 3'!$D$3 -> 260
B6: Biscuits | D6: =SUM(D3:D5) -> 725 | E6: =SUM(E3:E5) -> 655 | F6: =SUM(F3:F5) -> 730
C7: Excel-Consolidate-Data | D7: ='Report 1'!$H$3 -> 170 | E7: ='Report 1'!$I$3 -> 250 | F7: ='Report 1'!$J$3 -> 220
C8: Excel-Consolidate-Data | D8: ='Report 2'!$G$22 -> 235 | E8: ='Report 2'!$H$22 -> 205 | F8: ='Report 2'!$I$22 -> 175
C9: Excel-Consolidate-Data | D9: ='Report 3'!$B$10 -> 140 | E9: ='Report 3'!$C$10 -> 270 | F9: ='Report 3'!$D$10 -> 205
B10: Brownies | D10: =SUM(D7:D9) -> 545 | E10: =SUM(E7:E9) -> 725 | F10: =SUM(F7:F9) -> 600
C11: Excel-Consolidate-Data | D11: ='Report 1'!$H$4 -> 110 | F11: ='Report 1'!$J$4 -> 340
C12: Excel-Consolidate-Data | D12: ='Report 2'!$G$21 -> 310 | F12: ='Report 2'!$I$21 -> 220
C13: Excel-Consolidate-Data | D13: ='Report 3'!$B$5 -> 270 | E13: ='Report 3'!$C$5 -> 460 | F13: ='Report 3'!$D$5 -> 190
B14: Cakes | D14: =SUM(D11:D13) -> 690 | E14: =SUM(E11:E13) -> 460 | F14: =SUM(F11:F13) -> 750
C15: Excel-Consolidate-Data | D15: ='Report 1'!$H$5 -> 120 | E15: ='Report 1'!$I$5 -> 180 | F15: ='Report 1'!$J$5 -> 160
C16: Excel-Consolidate-Data | D16: ='Report 2'!$G$20 -> 280 | E16: ='Report 2'!$H$20 -> 175
C17: Excel-Consolidate-Data | D17: ='Report 3'!$B$13 -> 190 | E17: ='Report 3'!$C$13 -> 200 | F17: ='Report 3'!$D$13 -> 120
B18: Candy Bars | D18: =SUM(D15:D17) -> 590 | E18: =SUM(E15:E17) -> 555 | F18: =SUM(F15:F17) -> 280
C19: Excel-Consolidate-Data | D19: ='Report 1'!$H$6 -> 210 | E19: ='Report 1'!$I$6 -> 300 | F19: ='Report 1'!$J$6 -> 270
C20: Excel-Consolidate-Data | D20: ='Report 2'!$G$19 -> 180 | E20: ='Report 2'!$H$19 -> 250 | F20: ='Report 2'!$I$19 -> 165
C21: Excel-Consolidate-Data | D21: ='Report 3'!$B$20 -> 340 | E21: ='Report 3'!$C$20 -> 170 | F21: ='Report 3'!$D$20 -> 150
B22: Cheesecake | D22: =SUM(D19:D21) -> 730 | E22: =SUM(E19:E21) -> 720 | F22: =SUM(F19:F21) -> 585
C23: Excel-Consolidate-Data | D23: ='Report 1'!$H$7 -> 180 | E23: ='Report 1'!$I$7 -> 260 | F23: ='Report 1'!$J$7 -> 210
C24: Excel-Consolidate-Data | D24: ='Report 2'!$G$18 -> 340 | E24: ='Report 2'!$H$18 -> 155 | F24: ='Report 2'!$I$18 -> 170
C25: Excel-Consolidate-Data | D25: ='Report 3'!$B$6 -> 190 | E25: ='Report 3'!$C$6 -> 160 | F25: ='Report 3'!$D$6 -> 250
B26: Chocolate | D26: =SUM(D23:D25) -> 710 | E26: =SUM(E23:E25) -> 575 | F26: =SUM(F23:F25) -> 630
C27: Excel-Consolidate-Data | D27: ='Report 1'!$H$8 -> 130 | E27: ='Report 1'!$I$8 -> 190 | F27: ='Report 1'!$J$8 -> 150
C28: Excel-Consolidate-Data | D28: ='Report 2'!$G$17 -> 265 | E28: ='Report 2'!$H$17 -> 270 | F28: ='Report 2'!$I$17 -> 260
C29: Excel-Consolidate-Data | D29: ='Report 3'!$B$7 -> 145 | E29: ='Report 3'!$C$7 -> 220 | F29: ='Report 3'!$D$7 -> 300
B30: Cookies | D30: =SUM(D27:D29) -> 540 | E30: =SUM(E27:E29) -> 680 | F30: =SUM(F27:F29) -> 710
C31: Excel-Consolidate-Data | D31: ='Report 1'!$H$9 -> 175 | E31: ='Report 1'!$I$9 -> 245 | F31: ='Report 1'!$J$9 -> 215
C32: Excel-Consolidate-Data | D32: ='Report 2'!$G$16 -> 160 | E32: ='Report 2'!$H$16 -> 110 | F32: ='Report 2'!$I$16 -> 160
C33: Excel-Consolidate-Data | D33: ='Report 3'!$B$17 -> 210 | E33: ='Report 3'!$C$17 -> 310 | F33: ='Report 3'!$D$17 -> 215
B34: Croissants | D34: =SUM(D31:D33) -> 545 | E34: =SUM(E31:E33) -> 665 | F34: =SUM(F31:F33) -> 590
C35: Excel-Consolidate-Data | D35: ='Report 1'!$H$10 -> 150 | E35: ='Report 1'!$I$10 -> 210 | F35: ='Report 1'!$J$10 -> 190
C36: Excel-Consolidate-Data | D36: ='Report 2'!$G$15 -> 180 | E36: ='Report 2'!$H$15 -> 210 | F36: ='Report 2'!$I$15 -> 120
C37: Excel-Consolidate-Data | D37: ='Report 3'!$B$11 -> 290 | E37: ='Report 3'!$C$11 -> 245 | F37: ='Report 3'!$D$11 -> 180
B38: Cupcakes | D38: =SUM(D35:D37) -> 620 | E38: =SUM(E35:E37) -> 665 | F38: =SUM(F35:F37) -> 490
C39: Excel-Consolidate-Data | D39: ='Report 1'!$H$11 -> 160 | F39: ='Report 1'!$J$11 -> 180
C40: Excel-Consolidate-Data | D40: ='Report 2'!$G$14 -> 140 | E40: ='Report 2'!$H$14 -> 215 | F40: ='Report 2'!$I$14 -> 200
C41: Excel-Consolidate-Data | D41: ='Report 3'!$B$8 -> 310 | E41: ='Report 3'!$C$8 -> 140 | F41: ='Report 3'!$D$8 -> 160
...

Sheet static
B1: Jan | C1: Feb | D1: Mar
A2: Biscuits | B2: 725 | C2: 655 | D2: 730
A3: Brownies | B3: 545 | C3: 725 | D3: 600
A4: Cakes | B4: 690 | C4: 460 | D4: 750
A5: Candy Bars | B5: 590 | C5: 555 | D5: 280
A6: Cheesecake | B6: 730 | C6: 720 | D6: 585
A7: Chocolate | B7: 710 | C7: 575 | D7: 630
A8: Cookies | B8: 540 | C8: 680 | D8: 710
A9: Croissants | B9: 545 | C9: 665 | D9: 590
A10: Cupcakes | B10: 620 | C10: 665 | D10: 490
A11: Donuts | B11: 610 | C11: 355 | D11: 540
A12: Fudge | B12: 580 | C12: 675 | D12: 560
A13: Ice-cream | B13: 530 | C13: 605 | D13: 615
... A21: Waffles | B21: 505 | C21: 585 | D21: 550
